Workbook
Name Inflation: '1-P&L Modified'!$B$3
Name Preliminary_Analysis: WELCOME!$B$27
Name VAT: '1-F&B'!$B$5

Sheet WELCOME
B2: HOTEL ASSET MANAGEMENT – BOSC 5 - Team 5
B3: Radisson Blue - Wiesbaden
B5: HONOUR CODE As an EHL Hospitality Business School student, I uphold and defend academic integrity, academic rigor, and academic liberty as core values of higher learning. I attest, on my word of honor, that work submitted in my name is my own work and that any ideas or materials used in support of this work which is not originally my own, including AI-generated or assisted text, are cited and referenced accordingly in APA format.
B11: Students Team
B12: Team 5
F13: RADISSON BLU SCHWARZER BOCK HOTEL
B14: NAME | C14: LAST NAME | D14: STUDENT ID
B15: Matteo | C15: DELFINI | D15: 693625229
B16: Sophie | C16: LUSCHER | D16: 683 600 659
B17: Luca | C17: STETTLER | D17: 658937790
B18: Titouan | C18: GUYOT | D18: 704826420
B19: Margot | C19: CONCEPRIO | D19: 646947764
B20: Emilie | C20: KUSTER | D20: 651927774
B21: Daniella | C21: HALLEN | D21: 608900893
B22: Alexandre | C22: CARBONI | D22: 557 689 718
B24: Table of Content
B26: Sheet | D26: Description
B27: Preliminary Analysis | D27: Market and asset diagnosis (STR trends, comp set benchmarking, historical KPIs, key underperformance drivers, positioning).
B28: Assumptions | D28: Central assumptions hub (ADR/Occ growth, inflation, fees, RR, discount rate, cap rate, sales costs, disruption).
B29: P&L Normal Situation | D29: 10-year forecast without CAPEX (baseline) + baseline market value.
B30: 1-P&L Modified | D30: 10-year forecast with CAPEX / repositioning (pro forma) + market value with CAPEX.
B31: 1-F&B Details | D31: Detailed F&B build-up (covers, average check, seat occupancy, brasserie/café concepts) + benchmarks.
B32: 1-Capex | D32: Detailed CAPEX budget by area and category (FF&E / soft goods / construction + fees/contingency).
B33: 1-Capex Planning | D33: CAPEX phasing (monthly/weekly), room cluster sequencing, and disruption/OOO assumptions.
B34: 1-Incremental Cash Flow | D34: Incremental cash flows (With–Without), total and by department, with KPIs (NPV/IRR/payback/yield).
B35: 1-Sensitivity | D35: Scenario and sensitivity tests (±ADR, ±Occ) with impact on GOP/EBITDA and NPV/IRR.
B36: Appendix 1-STR Trend | D36: STR comp-set trends (Occ/ADR/RevPAR + MPI/ARI/RGI) supporting demand, pricing, and baseline gap.
B37: Appendix 2- Graphics | D37: Monthly Occ% and ADR seasonality (Frankfurt Rhine-Main Upper Upscale) supporting seasonality and phasing assumptions.

Sheet PRELIMINARY ANALYSIS
A1: Preliminary Analysis
B4: 1. COMPSET
B5: *Based on the STR Report Frankfurt Rhine-Main - Upper upscale
B6: HOTEL NAME | C6: CLASS | D6: ADR | E6: # ROOMS | F6: REGION | G6: SPA | H6: RESTAURANTS | I6: ROOM SERVICE | J6: POOL | K6: MEETING ROOMS | L6: WEBSITE
B7: Radisson Blue | C7: Upper Upscale | D7: 143.32 | E7: 142 | F7: Weisbaden / urban | G7: yes | H7: yes | I7: no | J7: yes | K7: yes | L7: LINK
B8: Hyatt Regency Mainz | C8: Upper Upscale | D8: 150.21 | E8: 268 | F8: Mainz / urban | G8: yes | H8: yes | I8: yes | J8: yes | K8: yes | L8: LINK
B9: Dorint Pallas Wiesbaden | C9: Upscale | D9: 114.46 | E9: 297 | F9: Weisbaden / urban | G9: yes | H9: yes , 2 | I9: yes | J9: no | K9: yes | L9: LINK
B10: Hotel Orianen | C10: Upper Upscale | D10: 150.21 | E10: 80 | F10: Weisbaden / urban | G10: no | H10: yes | I10: yes | J10: yes | K10: yes | L10: LINK
B11: Mercure Hotel Wiesbaden City | C11: Upper - Midscale | D11: 73.69 | E11: 235 | F11: Weisbaden / urban | G11: yes | H11: yes | I11: yes | J11: yes | K11: yes | L11: LINK
B12: Hotel Nassauer Hof Wiesbaden | C12: Luxury | D12: 241.82 | E12: 159 | F12: Weisbaden / suburban | G12: yes | H12: yes, 2 | I12: yes | J12: yes | K12: yes | L12: LINK
B13: The primary comp set was selected based on similar positioning (Upscale/Upper-Upscale), location within the Rhine-Main corporate area, and similar service level. Luxury and Upper-Midscale properties are used solely for positioning analysis.
B16: 2. ADR
B18: HISTORICAL ADR GROWTH RATE | D18: DEPRECIATION RATE | F18: HISTORICAL INFLATION | H18: EXPECTED FUTURE INFLATION | J18: ADR GROWTH RATE
B19: *Based on the STR Report Frankfurt Rhine-Main - Upper upscale | D19: Source: Real Estate class, -1% because building is old | F19: https://www.rateinflation.com/consumer-price-index/germany-historical-cpi/?utm | H19: https://www.theglobaleconomy.com/Germany/inflation_outlook_imf/?utm_source
B20: Year | C20: Frankfurt Rhine-Main Upper Upscale | D20: Real Depreciation | E20: =-1% -> -0.01 | F20: Year | G20: CPI | H20: Year | I20: Inflation rate | J20: Historical ADR Growth rate | K20: =_xlfn.RRI(B32-B21,C21,C32) -> 0.01440779
B21: 2013 | C21: ='APPENDIX 1-STR Trend '!P27 -> 131.98999 | F21: 2024 | G21: 119.3 | H21: 2025 | I21: 0.0176 | J21: Real depreciation | K21: =-1% -> -0.01
B22: 2014 | C22: ='APPENDIX 1-STR Trend '!P28 -> 129.9366 | F22: 2023 | G22: 116.7 | H22: 2026 | I22: 0.0199 | J22: Historical inflation | K22: =-_xlfn.RRI(F21-F32,G32,G21) -> -0.017569355
B23: 2015 | C23: ='APPENDIX 1-STR Trend '!P29 -> 135.83353 | F23: 2022 | G23: 110.2 | H23: 2027 | I23: 0.0211 | J23: Expected future inflation | K23: =AVERAGE(I21:I31) -> 0.021181818
B24: 2016 | C24: ='APPENDIX 1-STR Trend '!P30 -> 133.92902 | F24: 2021 | G24: 109.1 | H24: 2028 | I24: 0.0218
B25: 2017 | C25: ='APPENDIX 1-STR Trend '!P31 -> 139.26257 | F25: 2020 | G25: 105.8 | H25: 2029 | I25: 0.0218 | J25: ADR GROWTH RATE | K25: =SUM(K20:K23) -> 0.0080202527
B26: 2018 | C26: ='APPENDIX 1-STR Trend '!P32 -> 139.82464 | F26: 2019 | G26: 105.3 | H26: 2030 | I26: 0.0218
B27: 2019 | C27: ='APPENDIX 1-STR Trend '!P33 -> 140.51502 | F27: 2018 | G27: 103.8 | H27: 2031 | I27: 0.0218
B28: 2020 | C28: ='APPENDIX 1-STR Trend '!P34 -> 126.00649 | F28: 2017 | G28: 102 | H28: 2032 | I28: 0.0218
B29: 2021 | C29: ='APPENDIX 1-STR Trend '!P35 -> 116.60951 | F29: 2016 | G29: 100.5 | H29: 2033 | I29: 0.0218
B30: 2022 | C30: ='APPENDIX 1-STR Trend '!P36 -> 149.95474 | F30: 2015 | G30: 100 | H30: 2034 | I30: 0.0218
B31: 2023 | C31: ='APPENDIX 1-STR Trend '!P37 -> 154.01433 | F31: 2014 | G31: 99.4 | H31: 2035 | I31: 0.0218
B32: 2024 | C32: ='APPENDIX 1-STR Trend '!P38 -> 154.48251 | F32: 2013 | G32: 98.5
B35: 3. OCCUPANCY DISCOUNT RATE, CAP RATE
B37: OCCUPANCY | E37: DISCOUNT RATE
B38: *Based on the STR Report Frankfurt Rhine-Main - Upper upscale | E38: Riskfree* | F38: 0.0285
B39: Years | C39: Occupancy (%) | E39: + Sector Premium | F39: =6.3%-5.2% -> 0.011
B40: ='APPENDIX 1-STR Trend '!B9 -> 2013 | C40: ='APPENDIX 1-STR Trend '!P9 -> 65.663899 | E40: + City/submarket Premium** | F40: 0.01
B41: ='APPENDIX 1-STR Trend '!B10 -> 2014 | C41: ='APPENDIX 1-STR Trend '!P10 -> 68.63277 | E41: + Property Premium*** | F41: 0.02
B42: ='APPENDIX 1-STR Trend '!B11 -> 2015 | C42: ='APPENDIX 1-STR Trend '!P11 -> 70.237815 | E42: = Discount Rate | F42: =SUM(F38:F41) -> 0.0695
B43: ='APPENDIX 1-STR Trend '!B12 -> 2016 | C43: ='APPENDIX 1-STR Trend '!P12 -> 70.923591 | E43: * https://tradingeconomics.com/germany/government-bond-yield | H43: Allemagne : 6.3 HMA | I43: Allemagne : 5.2 Prime Lease
B44: ='APPENDIX 1-STR Trend '!B13 -> 2017 | C44: ='APPENDIX 1-STR Trend '!P13 -> 72.891453 | E44: **City / Submarket Premium 1% because Wiesbaden is not a prime location.
B45: ='APPENDIX 1-STR Trend '!B14 -> 2018 | C45: ='APPENDIX 1-STR Trend '!P14 -> 72.390969 | E45: ***Property Premium 2% because it's an old building 1486 year of construction
B46: ='APPENDIX 1-STR Trend '!B15 -> 2019 | C46: ='APPENDIX 1-STR Trend '!P15 -> 69.854822
B47: ='APPENDIX 1-STR Trend '!B16 -> 2020 | C47: ='APPENDIX 1-STR Trend '!P16 -> 30.359108
B48: ='APPENDIX 1-STR Trend '!B17 -> 2021 | C48: ='APPENDIX 1-STR Trend '!P17 -> 32.094927
...

Sheet ASSUMPTIONS
A3: P&L ASSUMPTIONS
A5: P&L | B5: METRIC | C5: STR REPORT 2023 | D5: 2024 | E5: Adjustment | F5: NEW | G5: EXPLINATION
A6: ADR | C6: ='APPENDIX 1-STR Trend '!I45 -> 179.03 | D6: =' P&L Normal Situation'!X12 -> 119.69 | E6: See comment | G6: Increase thanks to repositionning and white label contract (see detailes on P&L Modified) | I6: Base management fees | J6: =AVERAGE(2.77%,3.08%) -> 0.02925
A7: Occupancy % | C7: ='APPENDIX 1-STR Trend '!I44 -> 0.618 | D7: =' P&L Normal Situation'!X11 -> 0.743 | E7: See comment | G7: Decrease due to renovation than Increase due to repositionning + branding (see detailes on P&L Modified)
A8: Operating Revenue
A9: Rooms | B9: % of TREV | C9: ='APPENDIX 1-STR Trend '!E54/100 -> 0.713 | D9: =' P&L Normal Situation'!Y18 -> 0.73457266 | E9: See comment | F9: - | G9: Depending on ADR et Occ
A10: Food and Beverage | B10: % of TREV | C10: =SUM('APPENDIX 1-STR Trend '!E55:E57)/100 -> 0.245 | D10: =' P&L Normal Situation'!Y19 -> 0.17939272 | E10: See comment | F10: - | G10: Increase: New F&B outlets,(see detailes on F&B sheet)
A11: Spa | B11: % of TREV | C11: - | D11: =' P&L Normal Situation'!Z20 -> 8.013814 | E11: 0.15 | F11: =D11*(1+E11) -> 9.2158862 | G11: Adjustment for repositionning (bleisure)
A12: Other | B12: % of TREV | C12: ='APPENDIX 1-STR Trend '!E58/100 -> 0.015 | D12: =' P&L Normal Situation'!Z21 -> 6.0079975 | E12: 0.15 | F12: =D12*(1+E12) -> 6.9091971 | G12: Higer quality meeting rooms allowing higher prices
A13: Departemental Expenses
A14: Rooms | B14: % of Dep. Rev. | C14: ='APPENDIX 1-STR Trend '!E63/100 -> 0.29 | D14: =' P&L Normal Situation'!Y24 -> 0.34198572 | E14: -0.035 | F14: =SUM(D14:E14) -> 0.30698572 | G14: Decrease: Cost per room sold remain stable and better cost control thanks to franchise standards
A15: Food and Beverage | B15: % of Dep. Rev. | C15: ='APPENDIX 1-STR Trend '!E64/100 -> 0.818 | D15: =' P&L Normal Situation'!Y25 -> 1.003543 | E15: See comment | F15: - | G15: Decrease: New F&B outlets (see F&B sheet)
A16: Spa | B16: % of Dep. Rev. | C16: - | D16: =' P&L Normal Situation'!Y26 -> 0.81882665 | E16: -0.17 | F16: =SUM(D16:E16) -> 0.64882665 | G16: Decrease : thanks to renovation
A17: Other | B17: % of Dep. Rev. | C17: ='APPENDIX 1-STR Trend '!E65/100 -> 0.37 | D17: =' P&L Normal Situation'!Y27 -> 0.5387931 | E17: -0.17 | F17: =SUM(D17:E17) -> 0.3687931 | G17: Decrease : thanks to renovation
A18: Undistributed Operating Expenses
A19: Aministrative and General | B19: PAR | C19: ='APPENDIX 1-STR Trend '!G75 -> 5079.69 | D19: ='1-P&L Modified'!AA30 -> 2676.0563 | E19: =-10% -> -0.1 | F19: =D19*(1+E19) -> 2408.4507 | G19: Decrease: better efficency thanks to Accor
A20: Sales And Marketing | B20: PAR | C20: ='APPENDIX 1-STR Trend '!G77 -> 3685.67 | D20: ='1-P&L Modified'!AA31 -> 1619.7183 | E20: 0 | F20: =D20*(1+E20) -> 1619.7183 | G20: New outlets open to external need new promotion (Brasserie+café), less marketing fees thanks to franchise | I20: https://hvs.com/PaidPublications/Samples/Excerpts_HVS%20Guide%20to%20Hotel%20Management%20Contracts%202020.pdf
A21: Franchise Fees (royalty, loyalty, and marketing) | B21: % of room Rev | D21: ='1-P&L Modified'!AA32 -> 0 | E21: =5%+2% -> 0.07 | F21: =SUM(D21:E21) -> 0.07 | G21: New Franchise contract 5% Royaltees + 2% marketing contribution | I21: https://www.hvs.com/article/9912-a-new-approach-to-hotel-management-fees
A22: Heat light and Power | B22: PAR | C22: ='APPENDIX 1-STR Trend '!G79 -> 3418.13 | D22: ='1-P&L Modified'!AA33 -> 2394.3662 | E22: -0.05 | F22: =D22*(1+E22) -> 2274.6479 | G22: Decrease: thanks to ESG renovations (LED lights)
A23: Repairs and Maintenance | B23: PAR | C23: ='APPENDIX 1-STR Trend '!G80 -> 2947.86 | D23: ='1-P&L Modified'!AA34 -> 2816.9014 | E23: 0.1 | F23: =D23*(1+E23) -> 3098.5915 | G23: Increase: due to new F&B outlets
A24: Management Fees | I24: RETAIL HAIRDRESSER & PHONE STORE | J24: €/SQM/MONTH | K24: SOURCE
A25: Base Management Fee | B25: % of TREV | C25: ='APPENDIX 1-STR Trend '!E84/100 -> 0.021 | D25: ='1-P&L Modified'!Y38 -> 0 | E25: 0.03 | F25: =D25+E25 -> 0.03 | G25: New white label management contract | J25: 36.74 | K25: https://www.ihk.de/wiesbaden/wirtschaftspolitik/region/gewerbeflaechen-und-mietpreise/mietpreisspiegel-1255370
A26: Incentive Management Fee | B26: % of (Gross operating profit) | C26: ='APPENDIX 1-STR Trend '!E85/100 -> 0.005 | D26: ='1-P&L Modified'!Y39 -> 0 | E26: 0.08 | F26: =D26+E26 -> 0.08 | G26: New white label management contract | J26: =4000/130.32 -> 30.693677 | K26: https://www.immobilienscout24.de/expose/160771843?referrer=HYBRID_VIEW_MAP&searchId=c63438fd-bbf2-3de9-afaf-3124b02ce239&searchUrl=%2Fde%2Fhessen%2Fwiesbaden%2Fgastronomie-mieten%3Fbbox%3Dc2hycEhzZWZxQH1mQj8-c3JFfGZCPw..&searchType=district#/
A27: Non-operating Income & Expenses | J27: =4000/115.09 -> 34.755409 | K27: https://www.immobilienscout24.de/expose/162096020?referrer=HYBRID_VIEW_MAP&searchId=c63438fd-bbf2-3de9-afaf-3124b02ce239&searchUrl=%2Fde%2Fhessen%2Fwiesbaden%2Fgastronomie-mieten%3Fbbox%3Dc2hycEhzZWZxQH1mQj8-c3JFfGZCPw..&searchType=district#/
A28: Non-Operating Income | B28: % tot. operating rev. | C28: -0.001 | J28: =1700/96 -> 17.708333 | K28: https://www.immobilienscout24.de/expose/162519246?referrer=HYBRID_VIEW_MAP_GROUPED&searchId=c63438fd-bbf2-3de9-afaf-3124b02ce239&searchUrl=%2Fde%2Fhessen%2Fwiesbaden%2Fgastronomie-mieten%3Fbbox%3Dc2hycEhzZWZxQH1mQj8-c3JFfGZCPw..&searchType=district#/
A29: Retail income | F29: =J34*90*12 -> 32740.017 | G29: Estimated rental price by benchmark (retail shops) | J29: =2400/193 -> 12.435233 | K29: https://www.immobilienscout24.de/expose/153822589?referrer=HYBRID_VIEW_MAP_GROUPED&searchId=c63438fd-bbf2-3de9-afaf-3124b02ce239&searchUrl=%2Fde%2Fhessen%2Fwiesbaden%2Fgastronomie-mieten%3Fbbox%3Dc2hycEhzZWZxQH1mQj8-c3JFfGZCPw..&searchType=district#/
A30: Rent | B30: PAR | C30: ='APPENDIX 1-STR Trend '!G90 -> 7467 | J30: =8100/290 -> 27.931034 | K30: https://www.immobilienscout24.de/expose/160736004?referrer=HYBRID_VIEW_MAP&searchId=a7cf4782-ca5a-3849-a6f4-7a39745c5e5e&searchUrl=%2Fde%2Fhessen%2Fwiesbaden%2Feinzelhandel-mieten%3Fbbox%3DcXdycEhhdWVxQH1mQj8-c3JFfGZCPw..&searchType=district#/
A31: Property Taxes & Insurance | B31: PAR | C31: ='APPENDIX 1-STR Trend '!G91+'APPENDIX 1-STR Trend '!G92 -> 366 | D31: ='1-P&L Modified'!AA48 -> 316.90141 | E31: 0.05 | F31: =D31*(1+E31) -> 332.74648 | G31: Increase: Due to new value with capex + outlets | J31: =3800/105 -> 36.190476 | K31: https://www.immobilienscout24.de/expose/157437826?referrer=HYBRID_VIEW_MAP&searchId=a7cf4782-ca5a-3849-a6f4-7a39745c5e5e&searchUrl=%2Fde%2Fhessen%2Fwiesbaden%2Feinzelhandel-mieten%3Fbbox%3Dc3ZzcEhnYmdxQF9zQD8-eWhCfnJAPw..&searchType=district#/
J32: =6000/145 -> 41.37931 | K32: https://www.immobilienscout24.de/expose/162664184?referrer=HYBRID_VIEW_MAP_GROUPED&searchId=a7cf4782-ca5a-3849-a6f4-7a39745c5e5e&searchUrl=%2Fde%2Fhessen%2Fwiesbaden%2Feinzelhandel-mieten%3Fbbox%3Dd2t0cEhhdmdxQF9ZPz99c0B_WD8.&searchType=district#/
J33: 35 | K33: https://www.immobilienscout24.de/expose/164275457?referrer=HYBRID_VIEW_MAP_GROUPED&searchId=a7cf4782-ca5a-3849-a6f4-7a39745c5e5e&searchUrl=%2Fde%2Fhessen%2Fwiesbaden%2Feinzelhandel-mieten%3Fbbox%3DX35zcEh5X2dxQF9zQD8-eWhCfnJAPw..&searchType=district#/
I34: Average | J34: =AVERAGE(J25:J33) -> 30.31483
A35: CAPEX ASSUMPTIONS
A37: CAPEX ADJUSMENT | B37: APPLY ON | C37: ADJUSMENT | D37: Source
A38: Architect fee | B38: Total N/A ajusted Capex | C38: 0.1 | D38: https://aron-studio.de/architect-costs-in-germany-a-comprehensive-guide/
A39: FF&E ajustement | B39: FF&E | C39: 0.15 | D39: https://www.hyhotelfurniture.com/blog/hotel-ff-e-costs.html | I39: LABOR ADJUSTMENT | J39: MEDIAN SALARY/YEAR | K39: SOURCE
A40: Contractor Markup | B40: Construction | C40: 0.15 | D40: https://switchhotelsolutions.com.au/hotel-renovation-budget-template-guide/ | I40: USA | J40: =45300*0.86 -> 38958 | K40: https://careers.usnews.com/best-jobs/construction-worker/salary
A41: Labor | B41: Total N/A ajusted Capex | C41: =J41/J40-1 -> 0.16879717 | I41: Germany | J41: =45534 -> 45534 | K41: https://www.salaryexpert.com/salary/job/construction-worker/germany?__cf_chl_tk=Eez7vyb9Bpvs49M77FDW2NqRe9mQJ9ZCfFsBeNN0ApA-1765468386-1.0.1.1-RSeoRcHPlRy50UhMkQrxzXbHBTbHebualtv_w0_N1LQ
A42: Contingency | B42: Total N/A ajusted Capex | C42: 0.1 | D42: HVS_Hotel Estimation Guide_2024
A43: Capex reserves check | B43: Total N/A ajusted Capex | C43: 0.06 | D43: https://www.costar.com/article/1366873980/capex-study-authors-4-reserves-not-enough
A44: Renovation time | D44: https://www.hyhotelfurniture.com/how-long-does-it-take-to-refurbish

Sheet  P&L Normal Situation
A1: P&L Normal Situation
A2: Hotel # rooms | B2: 142
A3: Expected future inflation | B3: ='PRELIMINARY ANALYSIS'!K23 -> 0.021181818
A4: ADR Growth Rate | B4: ='PRELIMINARY ANALYSIS'!K25 -> 0.0080202527
A5: Occupancy Growth Rate | B5: ='PRELIMINARY ANALYSIS'!C52 -> 0.0018682486
P6: COVID | AV6: Occupancy Stabilize form this year
A7: Year | B7: 2013 | D7: 2014 | F7: 2015 | H7: 2016 | J7: 2017 | L7: 2018 | N7: 2019 | P7: 2020 | R7: 2021 | T7: 2022 | V7: 2023 | X7: 2024 | AB7: 2025 | AF7: 2026 | AJ7: 2027 | AN7: 2028 | AR7: 2029 | AV7: 2030 | AZ7: 2031 | BD7: 2032 | BH7: 2033 | BL7: 2034 | BP7: 2035
A8: Days | B8: 365 | D8: 365 | F8: 365 | H8: 366 | J8: 365 | L8: 365 | N8: 365 | P8: 366 | R8: 365 | T8: 365 | V8: 365 | X8: 366 | AB8: 365 | AF8: 365 | AJ8: 365 | AN8: 366 | AR8: 365 | AV8: 365 | AZ8: 365 | BD8: 366 | BH8: 365 | BL8: 365 | BP8: 365
A9: Rooms Available | B9: =B8*$B$2 -> 51830 | D9: =D8*$B$2 -> 51830 | F9: =F8*$B$2 -> 51830 | H9: =H8*$B$2 -> 51972 | J9: =J8*$B$2 -> 51830 | L9: =L8*$B$2 -> 51830 | N9: =N8*$B$2 -> 51830 | P9: =P8*$B$2 -> 51972 | R9: =R8*$B$2 -> 51830 | T9: =T8*$B$2 -> 51830 | V9: =V8*$B$2 -> 51830 | X9: =X8*$B$2 -> 51972 | AB9: =AB8*$B$2 -> 51830 | AF9: =AF8*$B$2 -> 51830 | AJ9: =AJ8*$B$2 -> 51830 | AN9: =AN8*$B$2 -> 51972 | AR9: =AR8*$B$2 -> 51830 | AV9: =AV8*$B$2 -> 51830 | AZ9: =AZ8*$B$2 -> 51830 | BD9: =BD8*$B$2 -> 51972 | BH9: =BH8*$B$2 -> 51830 | BL9: =BL8*$B$2 -> 51830 | BP9: =BP8*$B$2 -> 51830
A10: Rooms Sold | B10: =B11*B9 -> 33406 | D10: =D11*D9 -> 28091.86 | F10: =F11*F9 -> 38561.52 | H10: =H11*H9 -> 40174.356 | J10: =J11*J9 -> 37576.75 | L10: =L11*L9 -> 38717.01 | N10: =N11*N9 -> 40220.08 | P10: =P11*P9 -> 11122.008 | R10: =R11*R9 -> 11765.41 | T10: =T11*T9 -> 23738.14 | V10: =V11*V9 -> 32963.88 | X10: =X11*X9 -> 38615.196 | AB10: =ROUNDDOWN(AB9*AB11,0) -> 38581 | AF10: =ROUNDDOWN(AF9*AF11,0) -> 38653 | AJ10: =ROUNDDOWN(AJ9*AJ11,0) -> 38725 | AN10: =ROUNDDOWN(AN9*AN11,0) -> 38904 | AR10: =ROUNDDOWN(AR9*AR11,0) -> 38870 | AV10: =ROUNDDOWN(AV9*AV11,0) -> 38943 | AZ10: =ROUNDDOWN(AZ9*AZ11,0) -> 38943 | BD10: =ROUNDDOWN(BD9*BD11,0) -> 39050 | BH10: =ROUNDDOWN(BH9*BH11,0) -> 38943 | BL10: =ROUNDDOWN(BL9*BL11,0) -> 38943 | BP10: =ROUNDDOWN(BP9*BP11,0) -> 38943
A11: Occupancy | B11: 0.64453019 | D11: 0.542 | F11: 0.744 | H11: 0.773 | J11: 0.725 | L11: 0.747 | N11: 0.776 | P11: 0.214 | R11: 0.227 | T11: 0.458 | V11: 0.636 | X11: 0.743 | AB11: =X11*(1+$B$5) -> 0.74438811 | AF11: =AB11*(1+$B$5) -> 0.74577881 | AJ11: =AF11*(1+$B$5) -> 0.74717211 | AN11: =AJ11*(1+$B$5) -> 0.74856801 | AR11: =AN11*(1+$B$5) -> 0.74996653 | AV11: =AR11*(1+$B$5) -> 0.75136765 | AZ11: =AV11 -> 0.75136765 | BD11: =AZ11 -> 0.75136765 | BH11: =BD11 -> 0.75136765 | BL11: =BH11 -> 0.75136765 | BP11: =BL11 -> 0.75136765
A12: ADR | B12: 112.49476 | D12: 116 | F12: 115 | H12: 117.25 | J12: 125.93 | L12: 126.6 | N12: 125.6 | P12: 108.9 | R12: 115.4 | T12: 121.7 | V12: 127.12 | X12: 119.69 | AB12: =X12*(1+$B$4) -> 120.64994 | AF12: =AB12*(1+$B$4) -> 121.61759 | AJ12: =AF12*(1+$B$4) -> 122.59299 | AN12: =AJ12*(1+$B$4) -> 123.57622 | AR12: =AN12*(1+$B$4) -> 124.56733 | AV12: =AR12*(1+$B$4) -> 125.56639 | AZ12: =AV12*(1+$B$4) -> 126.57347 | BD12: =AZ12*(1+$B$4) -> 127.58862 | BH12: =BD12*(1+$B$4) -> 128.61191 | BL12: =BH12*(1+$B$4) -> 129.64341 | BP12: =BL12*(1+$B$4) -> 130.68318
A13: RevPAR | B13: 72.50627 | D13: 62.872 | F13: 85.56 | H13: 90.63425 | J13: 91.29925 | L13: 94.5702 | N13: 97.4656 | P13: 23.3046 | R13: 26.1958 | T13: 55.7386 | V13: 80.84832 | X13: 88.92967 | AB13: =AB11*AB12 -> 89.810384 | AF13: =AF11*AF12 -> 90.699819 | AJ13: =AJ11*AJ12 -> 91.598064 | AN13: =AN11*AN12 -> 92.505204 | AR13: =AR11*AR12 -> 93.421328 | AV13: =AV11*AV12 -> 94.346524 | AZ13: =AZ11*AZ12 -> 95.103207 | BD13: =BD11*BD12 -> 95.865959 | BH13: =BH11*BH12 -> 96.634828 | BL13: =BL11*BL12 -> 97.409864 | BP13: =BP11*BP12 -> 98.191116
A14: TrevPar
B16: € | C16: % | D16: € | E16: % | F16: € | G16: % | H16: € | I16: % | J16: € | K16: % | L16: € | M16: % | N16: € | O16: % | P16: € | Q16: % | R16: € | S16: % | T16: € | U16: % | V16: € | W16: % | X16: € | Y16: % | Z16: POR | AA16: PAR | AB16: € | AC16: % | AD16: POR | AE16: PAR | AF16: € | AG16: % | AH16: POR | AI16: PAR | AJ16: € | AK16: % | AL16: POR | AM16: PAR | AN16: € | AO16: % | AP16: POR | AQ16: PAR | AR16: € | AS16: % | AT16: POR | AU16: PAR | AV16: € | AW16: % | AX16: POR | AY16: PAR | AZ16: € | BA16: % | BB16: POR | BC16: PAR | BD16: € | BE16: % | BF16: POR | BG16: PAR | BH16: € | BI16: % | BJ16: POR | BK16: PAR | BL16: € | BM16: % | BN16: POR | BO16: PAR | BP16: € | BQ16: % | BR16: POR | BS16: PAR
A17: Departemental Revenue
A18: Rooms | B18: 3758000 | C18: =B18/$B$22 -> 0.66031281 | D18: 3258000 | E18: =D18/$D$22 -> 0.65852012 | F18: 4433000 | G18: =F18/$F$22 -> 0.70170162 | H18: 4712000 | I18: =H18/$H$22 -> 0.70890616 | J18: 4734000 | K18: =J18/$J$22 -> 0.72250101 | L18: 4903000 | M18: =L18/$L$22 -> 0.73018246 | N18: 5038000 | O18: =N18/$N$22 -> 0.74406652 | P18: 1207877.4 | Q18: =P18/$P$22 -> 0.7537751 | R18: 1357728.3 | S18: =R18/$R$22 -> 0.70568795 | T18: 2888931.6 | U18: =T18/$T$22 -> 0.68502385 | V18: 4194000 | W18: =V18/$V$22 -> 0.75999808 | X18: 4623000 | Y18: =X18/$X$22 -> 0.73457266 | Z18: =X18/$X$10 -> 119.71971 | AA18: =X18/$B$2 -> 32556.338 | AB18: =AB10*AB12 -> 4654795.5 | AC18: =AB18/AB$22 -> 0.73607905 | AD18: =AB18/$AB$10 -> 120.64994 | AE18: =AB18/$B$2 -> 32780.25 | AF18: =AF10*AF12 -> 4700884.6 | AG18: =AF18/AF$22 -> 0.73762797 | AH18: =AF18/$AB$10 -> 121.84455 | AI18: =AF18/$B$2 -> 33104.821 | AJ18: =AJ10*AJ12 -> 4747413.6 | AK18: =AJ18/AJ$22 -> 0.73917103 | AL18: =AJ18/$AB$10 -> 123.05056 | AM18: =AJ18/$B$2 -> 33432.49 | AN18: =AN10*AN12 -> 4807609.2 | AO18: =AN18/AN$22 -> 0.7407082 | AP18: =AN18/$AB$10 -> 124.6108 | AQ18: =AN18/$B$2 -> 33856.403 | AR18: =AR10*AR12 -> 4841932.1 | AS18: =AR18/AR$22 -> 0.74223947 | AT18: =AR18/$AB$10 -> 125.50043 | AU18: =AR18/$B$2 -> 34098.114 | AV18: =AV10*AV12 -> 4889932 | AW18: =AV18/AV$22 -> 0.74376482 | AX18: =AV18/$AB$10 -> 126.74456 | AY18: =AV18/$B$2 -> 34436.141 | AZ18: =AZ10*AZ12 -> 4929150.5 | BA18: =AZ18/AZ$22 -> 0.74528425 | BB18: =AZ18/$AB$10 -> 127.76109 | BC18: =AZ18/$B$2 -> 34712.327 | BD18: =BD10*BD12 -> 4982335.5 | BE18: =BD18/BD$22 -> 0.74679773 | BF18: =BD18/$AB$10 -> 129.13962 | BG18: =BD18/$B$2 -> 35086.87 | BH18: =BH10*BH12 -> 5008533.6 | BI18: =BH18/BH$22 -> 0.74830526 | BJ18: =BH18/$AB$10 -> 129.81866 | BK18: =BH18/$B$2 -> 35271.363 | BL18: =BL10*BL12 -> 5048703.3 | BM18: =BL18/BL$22 -> 0.74980682 | BN18: =BL18/$AB$10 -> 130.85984 | BO18: =BL18/$B$2 -> 35554.249 | BP18: =BP10*BP12 -> 5089195.2 | BQ18: =BP18/BP$22 -> 0.75130239 | BR18: =BP18/$AB$10 -> 131.90936 | BS18: =BP18/$B$2 -> 35839.403
A19: Food and Bevarge | B19: 1391000 | C19: =B19/$B$22 -> 0.24441062 | D19: 1208000 | E19: =D19/$D$22 -> 0.24416584 | F19: 1297000 | G19: =F19/$F$22 -> 0.20530273 | H19: 1239000 | I19: =H19/$H$22 -> 0.18640381 | J19: 1293000 | K19: =J19/$J$22 -> 0.19733709 | L19: 1280000 | M19: =L19/$L$22 -> 0.19062483 | N19: 1194000 | O19: =N19/$N$22 -> 0.17634288 | P19: 200000 | Q19: =P19/$P$22 -> 0.12480987 | R19: 250000 | S19: =R19/$R$22 -> 0.12993909 | T19: 840000 | U19: =T19/$T$22 -> 0.19918091 | V19: 899000 | W19: =V19/$V$22 -> 0.16290851 | X19: 1129000 | Y19: =X19/$X$22 -> 0.17939272 | Z19: =X19/$X$10 -> 29.237195 | AA19: =X19/$B$2 -> 7950.7042 | AB19: =AD19*$AB$10 -> 1128000.2 | AC19: =AB19/AB$22 -> 0.17837461 | AD19: =Z19 -> 29.237195 | AE19: =AB19/$B$2 -> 7943.6634 | AF19: =AH19*AF$10 -> 1130105.3 | AG19: =AF19/AF$22 -> 0.17732775 | AH19: =AD19 -> 29.237195 | AI19: =AF19/$B$2 -> 7958.4879 | AJ19: =AL19*AJ$10 -> 1132210.4 | AK19: =AJ19/AJ$22 -> 0.17628485 | AL19: =AH19 -> 29.237195 | AM19: =AJ19/$B$2 -> 7973.3124 | AN19: =AP19*AN$10 -> 1137443.8 | AO19: =AN19/AN$22 -> 0.17524593 | AP19: =AL19 -> 29.237195 | AQ19: =AN19/$B$2 -> 8010.1677 | AR19: =AT19*AR$10 -> 1136449.8 | AS19: =AR19/AR$22 -> 0.174211 | AT19: =AP19 -> 29.237195 | AU19: =AR19/$B$2 -> 8003.1673 | AV19: =AX19*AV$10 -> 1138584.1 | AW19: =AV19/AV$22 -> 0.17318007 | AX19: =AT19 -> 29.237195 | AY19: =AV19/$B$2 -> 8018.1977 | AZ19: =BB19*AZ$10 -> 1138584.1 | BA19: =AZ19/AZ$22 -> 0.17215315 | BB19: =AX19 -> 29.237195 | BC19: =AZ19/$B$2 -> 8018.1977 | BD19: =BF19*BD$10 -> 1141712.4 | BE19: =BD19/BD$22 -> 0.17113024 | BF19: =BB19 -> 29.237195 | BG19: =BD19/$B$2 -> 8040.2285 | BH19: =BJ19*BH$10 -> 1138584.1 | BI19: =BH19/BH$22 -> 0.17011136 | BJ19: =BF19 -> 29.237195 | BK19: =BH19/$B$2 -> 8018.1977 | BL19: =BN19*BL$10 -> 1138584.1 | BM19: =BL19/BL$22 -> 0.16909651 | BN19: =BJ19 -> 29.237195 | BO19: =BL19/$B$2 -> 8018.1977 | BP19: =BR19*BP$10 -> 1138584.1 | BQ19: =BP19/BP$22 -> 0.1680857 | BR19: =BN19 -> 29.237195 | BS19: =BP19/$B$2 -> 8018.1977
A20: Spa | B20: 235242 | C20: =B20/$B$22 -> 0.041334036 | D20: 198457 | E20: =D20/$D$22 -> 0.040112931 | F20: 247500 | G20: =F20/$F$22 -> 0.03917689 | H20: 274860 | I20: =H20/$H$22 -> 0.041351856 | J20: 253240 | K20: =J20/$J$22 -> 0.038649378 | L20: 258760 | M20: =L20/$L$22 -> 0.038536001 | N20: 276900 | O20: =N20/$N$22 -> 0.040895597 | P20: 124560 | Q20: =P20/$P$22 -> 0.077731585 | R20: 174250 | S20: =R20/$R$22 -> 0.090567549 | T20: 303340 | U20: =T20/$T$22 -> 0.07192802 | V20: 297435 | W20: =V20/$V$22 -> 0.053898433 | X20: 309455 | Y20: =X20/$X$22 -> 0.049170924 | Z20: =X20/$X$10 -> 8.013814 | AA20: =X20/$B$2 -> 2179.2606 | AB20: =AD20*$AB$10 -> 309180.96 | AC20: =AB20/AB$22 -> 0.048891864 | AD20: =Z20 -> 8.013814 | AE20: =AB20/$B$2 -> 2177.3307 | AF20: =AH20*AF$10 -> 309757.95 | AG20: =AF20/AF$22 -> 0.048604923 | AH20: =AD20 -> 8.013814 | AI20: =AF20/$B$2 -> 2181.394 | AJ20: =AL20*AJ$10 -> 310334.95 | AK20: =AJ20/AJ$22 -> 0.048319069 | AL20: =AH20 -> 8.013814 | AM20: =AJ20/$B$2 -> 2185.4574 | AN20: =AP20*AN$10 -> 311769.42 | AO20: =AN20/AN$22 -> 0.048034305 | AP20: =AL20 -> 8.013814 | AQ20: =AN20/$B$2 -> 2195.5593 | AR20: =AT20*AR$10 -> 311496.95 | AS20: =AR20/AR$22 -> 0.047750635 | AT20: =AP20 -> 8.013814 | AU20: =AR20/$B$2 -> 2193.6405 | AV20: =AX20*AV$10 -> 312081.96 | AW20: =AV20/AV$22 -> 0.04746806 | AX20: =AT20 -> 8.013814 | AY20: =AV20/$B$2 -> 2197.7603 | AZ20: =BB20*AZ$10 -> 312081.96 | BA20: =AZ20/AZ$22 -> 0.047186583 | BB20: =AX20 -> 8.013814 | BC20: =AZ20/$B$2 -> 2197.7603 | BD20: =BF20*BD$10 -> 312939.44 | BE20: =BD20/BD$22 -> 0.046906207 | BF20: =BB20 -> 8.013814 | BG20: =BD20/$B$2 -> 2203.7989 | BH20: =BJ20*BH$10 -> 312081.96 | BI20: =BH20/BH$22 -> 0.046626935 | BJ20: =BF20 -> 8.013814 | BK20: =BH20/$B$2 -> 2197.7603 | BL20: =BN20*BL$10 -> 312081.96 | BM20: =BL20/BL$22 -> 0.046348768 | BN20: =BJ20 -> 8.013814 | BO20: =BL20/$B$2 -> 2197.7603 | BP20: =BR20*BP$10 -> 312081.96 | BQ20: =BP20/BP$22 -> 0.04607171 | BR20: =BN20 -> 8.013814 | BS20: =BP20/$B$2 -> 2197.7603
A21: Other | B21: 307000 | C21: =B21/$B$22 -> 0.053942531 | D21: 283000 | E21: =D21/$D$22 -> 0.057201104 | F21: 340000 | G21: =F21/$F$22 -> 0.053818757 | H21: 421000 | I21: =H21/$H$22 -> 0.063338178 | J21: 272000 | K21: =J21/$J$22 -> 0.041512521 | L21: 273000 | M21: =L21/$L$22 -> 0.040656703 | N21: 262000 | O21: =N21/$N$22 -> 0.038695004 | P21: 70000 | Q21: =P21/$P$22 -> 0.043683453 | R21: 142000 | S21: =R21/$R$22 -> 0.073805406 | T21: 185000 | U21: =T21/$T$22 -> 0.043867224 | V21: 128000 | W21: =V21/$V$22 -> 0.023194982 | X21: 232000 | Y21: =X21/$X$22 -> 0.036863694 | Z21: =X21/$X$10 -> 6.0079975 | AA21: =X21/$B$2 -> 1633.8028 | AB21: =AD21*$AB$10 -> 231794.55 | AC21: =AB21/AB$22 -> 0.036654481 | AD21: =Z21 -> 6.0079975 | AE21: =AB21/$B$2 -> 1632.356 | AF21: =AH21*AF$10 -> 232227.13 | AG21: =AF21/AF$22 -> 0.03643936 | AH21: =AD21 -> 6.0079975 | AI21: =AF21/$B$2 -> 1635.4023 | AJ21: =AL21*AJ$10 -> 232659.7 | AK21: =AJ21/AJ$22 -> 0.036225054 | AL21: =AH21 -> 6.0079975 | AM21: =AJ21/$B$2 -> 1638.4486 | AN21: =AP21*AN$10 -> 233735.13 | AO21: =AN21/AN$22 -> 0.036011565 | AP21: =AL21 -> 6.0079975 | AQ21: =AN21/$B$2 -> 1646.0221 | AR21: =AT21*AR$10 -> 233530.86 | AS21: =AR21/AR$22 -> 0.035798895 | AT21: =AP21 -> 6.0079975 | AU21: =AR21/$B$2 -> 1644.5835 | AV21: =AX21*AV$10 -> 233969.45 | AW21: =AV21/AV$22 -> 0.035587048 | AX21: =AT21 -> 6.0079975 | AY21: =AV21/$B$2 -> 1647.6722 | AZ21: =BB21*AZ$10 -> 233969.45 | BA21: =AZ21/AZ$22 -> 0.035376023 | BB21: =AX21 -> 6.0079975 | BC21: =AZ21/$B$2 -> 1647.6722 | BD21: =BF21*BD$10 -> 234612.3 | BE21: =BD21/BD$22 -> 0.035165824 | BF21: =BB21 -> 6.0079975 | BG21: =BD21/$B$2 -> 1652.1993 | BH21: =BJ21*BH$10 -> 233969.45 | BI21: =BH21/BH$22 -> 0.034956452 | BJ21: =BF21 -> 6.0079975 | BK21: =BH21/$B$2 -> 1647.6722 | BL21: =BN21*BL$10 -> 233969.45 | BM21: =BL21/BL$22 -> 0.034747909 | BN21: =BJ21 -> 6.0079975 | BO21: =BL21/$B$2 -> 1647.6722 | BP21: =BR21*BP$10 -> 233969.45 | BQ21: =BP21/BP$22 -> 0.034540197 | BR21: =BN21 -> 6.0079975 | BS21: =BP21/$B$2 -> 1647.6722
A22: Total Operating Revenue | B22: =SUM(B18:B21) -> 5691242 | C22: =B22/$B$22 -> 1 | D22: =SUM(D18:D21) -> 4947457 | E22: =D22/$D$22 -> 1 | F22: =SUM(F18:F21) -> 6317500 | G22: =F22/$F$22 -> 1 | H22: =SUM(H18:H21) -> 6646860 | I22: =H22/$H$22 -> 1 | J22: =SUM(J18:J21) -> 6552240 | K22: =J22/$J$22 -> 1 | L22: =SUM(L18:L21) -> 6714760 | M22: =L22/$L$22 -> 1 | N22: =SUM(N18:N21) -> 6770900 | O22: =N22/$N$22 -> 1 | P22: =SUM(P18:P21) -> 1602437.4 | Q22: =P22/$P$22 -> 1 | R22: =SUM(R18:R21) -> 1923978.3 | S22: =R22/$R$22 -> 1 | T22: =SUM(T18:T21) -> 4217271.6 | U22: =T22/$T$22 -> 1 | V22: =SUM(V18:V21) -> 5518435 | W22: =V22/$V$22 -> 1 | X22: =SUM(X18:X21) -> 6293455 | Y22: =X22/$X$22 -> 1 | Z22: =X22/$X$10 -> 162.97871 | AA22: =X22/$B$2 -> 44320.106 | AB22: =SUM(AB18:AB21) -> 6323771.2 | AC22: =AB22/$AB$22 -> 1 | AD22: =AB22/$AB$10 -> 163.90895 | AE22: =AB22/$B$2 -> 44533.6 | AF22: =SUM(AF18:AF21) -> 6372975 | AG22: =SUM(AG18:AG21) -> 1 | AH22: =SUM(AH18:AH21) -> 165.10356 | AI22: =AF22/$B$2 -> 44880.105 | AJ22: =SUM(AJ18:AJ21) -> 6422618.6 | AK22: =SUM(AK18:AK21) -> 1 | AL22: =SUM(AL18:AL21) -> 166.30956 | AM22: =AJ22/$B$2 -> 45229.708 | AN22: =SUM(AN18:AN21) -> 6490557.5 | AO22: =SUM(AO18:AO21) -> 1 | AP22: =SUM(AP18:AP21) -> 167.8698 | AQ22: =AN22/$B$2 -> 45708.152 | AR22: =SUM(AR18:AR21) -> 6523409.7 | AS22: =SUM(AS18:AS21) -> 1 | AT22: =SUM(AT18:AT21) -> 168.75944 | AU22: =AR22/$B$2 -> 45939.505 | AV22: =SUM(AV18:AV21) -> 6574567.5 | AW22: =SUM(AW18:AW21) -> 1 | AX22: =SUM(AX18:AX21) -> 170.00357 | AY22: =AV22/$B$2 -> 46299.771 | AZ22: =SUM(AZ18:AZ21) -> 6613786 | BA22: =SUM(BA18:BA21) -> 1 | BB22: =SUM(BB18:BB21) -> 171.02009 | BC22: =AZ22/$B$2 -> 46575.957 | BD22: =SUM(BD18:BD21) -> 6671599.7 | BE22: =SUM(BE18:BE21) -> 1 | BF22: =SUM(BF18:BF21) -> 172.39862 | BG22: =BD22/$B$2 -> 46983.096 | BH22: =SUM(BH18:BH21) -> 6693169.1 | BI22: =SUM(BI18:BI21) -> 1 | BJ22: =SUM(BJ18:BJ21) -> 173.07766 | BK22: =BH22/$B$2 -> 47134.994 | BL22: =SUM(BL18:BL21) -> 6733338.8 | BM22: =SUM(BM18:BM21) -> 1 | BN22: =SUM(BN18:BN21) -> 174.11884 | BO22: =BL22/$B$2 -> 47417.879 | BP22: =SUM(BP18:BP21) -> 6773830.7 | BQ22: =SUM(BQ18:BQ21) -> 1 | BR22: =SUM(BR18:BR21) -> 175.16837 | BS22: =BP22/$B$2 -> 47703.033
A23: Departemental Expenses
A24: Rooms | B24: 1294631 | C24: =B24/B18 -> 0.3445 | D24: 1161570.5 | E24: =D24/D18 -> 0.3565287 | F24: 1365913.7 | G24: =F24/F18 -> 0.308124 | H24: 1406202.2 | I24: =H24/H18 -> 0.29843 | J24: 1434000 | K24: =J24/J18 -> 0.30291508 | L24: 1391000 | M24: =L24/L18 -> 0.28370385 | N24: 1431000 | O24: =N24/N18 -> 0.28404129 | P24: 338205.68 | Q24: =P24/P18 -> 0.28 | R24: 380163.93 | S24: =R24/R18 -> 0.28 | T24: 808900.86 | U24: =T24/T18 -> 0.28 | V24: 1413000 | W24: =V24/V18 -> 0.33690987 | X24: 1581000 | Y24: =X24/X18 -> 0.34198572 | Z24: =X24/$X$10 -> 40.942431 | AA24: =X24/$B$2 -> 11133.803 | AB24: =AC24*AB18 -> 1591873.6 | AC24: =Y24 -> 0.34198572 | AD24: =AB24/$AB$10 -> 41.260558 | AE24: =AB24/$B$2 -> 11210.377 | AF24: =AG24*AF18 -> 1607635.4 | AG24: =AC24 -> 0.34198572 | AH24: =AF24/$AF$10 -> 41.591479 | AI24: =AF24/$B$2 -> 11321.376 | AJ24: =AK24*AJ18 -> 1623547.7 | AK24: =AG24 -> 0.34198572 | AL24: =AJ24/$AJ$10 -> 41.925053 | AM24: =AJ24/$B$2 -> 11433.434 | AN24: =AO24*AN18 -> 1644133.7 | AO24: =AK24 -> 0.34198572 | AP24: =AN24/$AN$10 -> 42.261302 | AQ24: =AN24/$B$2 -> 11578.406 | AR24: =AS24*AR18 -> 1655871.7 | AS24: =AO24 -> 0.34198572 | AT24: =AR24/$AR$10 -> 42.600249 | AU24: =AR24/$B$2 -> 11661.068 | AV24: =AW24*AV18 -> 1672286.9 | AW24: =AS24 -> 0.34198572 | AX24: =AV24/$AV$10 -> 42.941913 | AY24: =AV24/$B$2 -> 11776.669 | AZ24: =BA24*AZ18 -> 1685699.1 | BA24: =AW24 -> 0.34198572 | BB24: =AZ24/$AZ$10 -> 43.286318 | BC24: =AZ24/$B$2 -> 11871.12 | BD24: =BE24*BD18 -> 1703887.6 | BE24: =BA24 -> 0.34198572 | BF24: =BD24/$BD$10 -> 43.633485 | BG24: =BD24/$B$2 -> 11999.209 | BH24: =BI24*BH18 -> 1712847 | BI24: =BE24 -> 0.34198572 | BJ24: =BH24/$BH$10 -> 43.983437 | BK24: =BH24/$B$2 -> 12062.303 | BL24: =BM24*BL18 -> 1726584.5 | BM24: =BI24 -> 0.34198572 | BN24: =BL24/$BL$10 -> 44.336195 | BO24: =BL24/$B$2 -> 12159.045 | BP24: =BQ24*BP18 -> 1740432.1 | BQ24: =BM24 -> 0.34198572 | BR24: =BP24/$BL$10 -> 44.691783 | BS24: =BP24/$B$2 -> 12256.564
A25: Food and Beverage | B25: 1210091.6 | C25: =B25/B19 -> 0.86994363 | D25: 1102489.5 | E25: =D25/D19 -> 0.9126569 | F25: 1280953.9 | G25: =F25/F19 -> 0.98762827 | H25: 1267033.1 | I25: =H25/H19 -> 1.0226256 | J25: 1197000 | K25: =J25/J19 -> 0.92575406 | L25: 1099000 | M25: =L25/L19 -> 0.85859375 | N25: 1090000 | O25: =N25/N19 -> 0.91289782 | P25: 187134 | Q25: =P25/P19 -> 0.93567 | R25: 231175 | S25: =R25/R19 -> 0.9247 | T25: 770985.6 | U25: =T25/T19 -> 0.91784 | V25: 839000 | W25: =V25/V19 -> 0.93325918 | X25: 1133000 | Y25: =X25/X19 -> 1.003543 | Z25: =X25/$X$10 -> 29.340781 | AA25: =X25/$B$2 -> 7978.8732 | AB25: =AC25*AB19 -> 1131996.7 | AC25: =Y25 -> 1.003543 | AD25: =AB25/$AB$10 -> 29.340781 | AE25: =AB25/$B$2 -> 7971.8075 | AF25: =AG25*AF19 -> 1134109.2 | AG25: =AC25 -> 1.003543 | AH25: =AF25/$AF$10 -> 29.340781 | AI25: =AF25/$B$2 -> 7986.6845 | AJ25: =AK25*AJ19 -> 1136221.7 | AK25: =AG25 -> 1.003543 | AL25: =AJ25/$AJ$10 -> 29.340781 | AM25: =AJ25/$B$2 -> 8001.5615 | AN25: =AO25*AN19 -> 1141473.7 | AO25: =AK25 -> 1.003543 | AP25: =AN25/$AN$10 -> 29.340781 | AQ25: =AN25/$B$2 -> 8038.5474 | AR25: =AS25*AR19 -> 1140476.1 | AS25: =AO25 -> 1.003543 | AT25: =AR25/$AR$10 -> 29.340781 | AU25: =AR25/$B$2 -> 8031.5222 | AV25: =AW25*AV19 -> 1142618 | AW25: =AS25 -> 1.003543 | AX25: =AV25/$AV$10 -> 29.340781 | AY25: =AV25/$B$2 -> 8046.6058 | AZ25: =BA25*AZ19 -> 1142618 | BA25: =AW25 -> 1.003543 | BB25: =AZ25/$AZ$10 -> 29.340781 | BC25: =AZ25/$B$2 -> 8046.6058 | BD25: =BE25*BD19 -> 1145757.5 | BE25: =BA25 -> 1.003543 | BF25: =BD25/$BD$10 -> 29.340781 | BG25: =BD25/$B$2 -> 8068.7147 | BH25: =BI25*BH19 -> 1142618 | BI25: =BE25 -> 1.003543 | BJ25: =BH25/$BH$10 -> 29.340781 | BK25: =BH25/$B$2 -> 8046.6058 | BL25: =BM25*BL19 -> 1142618 | BM25: =BI25 -> 1.003543 | BN25: =BL25/$BL$10 -> 29.340781 | BO25: =BL25/$B$2 -> 8046.6058 | BP25: =BQ25*BP19 -> 1142618 | BQ25: =BM25 -> 1.003543 | BR25: =BP25/$BL$10 -> 29.340781 | BS25: =BP25/$B$2 -> 8046.6058
A26: Spa | B26: 176099.81 | C26: =B26/B20 -> 0.74859 | D26: 148562.93 | E26: =D26/D20 -> 0.74859 | F26: 185276.02 | G26: =F26/F20 -> 0.74859 | H26: 205757.45 | I26: =H26/H20 -> 0.74859 | J26: 189572.93 | K26: =J26/J20 -> 0.74859 | L26: 180200 | M26: =L26/L20 -> 0.69639821 | N26: 215400 | O26: =N26/N20 -> 0.77789816 | P26: 119378.3 | Q26: =P26/P20 -> 0.9584 | R26: 167001.2 | S26: =R26/R20 -> 0.9584 | T26: 238380 | U26: =T26/T20 -> 0.78585086 | V26: 239975 | W26: =V26/V20 -> 0.80681493 | X26: 253390 | Y26: =X26/X20 -> 0.81882665 | Z26: =X26/$X$10 -> 6.5619245 | AA26: =X26/$B$2 -> 1784.4366 | AB26: =AC26*AB20 -> 253165.61 | AC26: =Y26 -> 0.81882665 | AD26: =AB26/$AB$10 -> 6.5619245 | AE26: =AB26/$B$2 -> 1782.8564 | AF26: =AG26*AF20 -> 253638.07 | AG26: =AC26 -> 0.81882665 | AH26: =AF26/$AF$10 -> 6.5619245 | AI26: =AF26/$B$2 -> 1786.1836 | AJ26: =AK26*AJ20 -> 254110.53 | AK26: =AG26 -> 0.81882665 | AL26: =AJ26/$AJ$10 -> 6.5619245 | AM26: =AJ26/$B$2 -> 1789.5107 | AN26: =AO26*AN20 -> 255285.11 | AO26: =AK26 -> 0.81882665 | AP26: =AN26/$AN$10 -> 6.5619245 | AQ26: =AN26/$B$2 -> 1797.7825 | AR26: =AS26*AR20 -> 255062 | AS26: =AO26 -> 0.81882665 | AT26: =AR26/$AR$10 -> 6.5619245 | AU26: =AR26/$B$2 -> 1796.2113 | AV26: =AW26*AV20 -> 255541.03 | AW26: =AS26 -> 0.81882665 | AX26: =AV26/$AV$10 -> 6.5619245 | AY26: =AV26/$B$2 -> 1799.5847 | AZ26: =BA26*AZ20 -> 255541.03 | BA26: =AW26 -> 0.81882665 | BB26: =AZ26/$AZ$10 -> 6.5619245 | BC26: =AZ26/$B$2 -> 1799.5847 | BD26: =BE26*BD20 -> 256243.15 | BE26: =BA26 -> 0.81882665 | BF26: =BD26/$BD$10 -> 6.5619245 | BG26: =BD26/$B$2 -> 1804.5292 | BH26: =BI26*BH20 -> 255541.03 | BI26: =BE26 -> 0.81882665 | BJ26: =BH26/$BH$10 -> 6.5619245 | BK26: =BH26/$B$2 -> 1799.5847 | BL26: =BM26*BL20 -> 255541.03 | BM26: =BI26 -> 0.81882665 | BN26: =BL26/$BL$10 -> 6.5619245 | BO26: =BL26/$B$2 -> 1799.5847 | BP26: =BQ26*BP20 -> 255541.03 | BQ26: =BM26 -> 0.81882665 | BR26: =BP26/$BL$10 -> 6.5619245 | BS26: =BP26/$B$2 -> 1799.5847
A27: Other | B27: 96477.404 | C27: =B27/B21 -> 0.31425865 | D27: 180000 | E27: =D27/D21 -> 0.6360424 | F27: 162132.45 | G27: =F27/F21 -> 0.47686014 | H27: 137616.69 | I27: =H27/H21 -> 0.3268805 | J27: 135000 | K27: =J27/J21 -> 0.49632353 | L27: 115000 | M27: =L27/L21 -> 0.42124542 | N27: 128000 | O27: =N27/N21 -> 0.48854962 | P27: 128000 | Q27: =P27/P21 -> 1.8285714 | R27: 128000 | S27: =R27/R21 -> 0.90140845 | T27: 128000 | U27: =T27/T21 -> 0.69189189 | V27: 110000 | W27: =V27/V21 -> 0.859375 | X27: 125000 | Y27: =X27/X21 -> 0.5387931 | Z27: =X27/$X$10 -> 3.2370676 | AA27: =X27/$B$2 -> 880.28169 | AB27: =AC27*AB21 -> 124889.31 | AC27: =Y27 -> 0.5387931 | AD27: =AB27/$AB$10 -> 3.2370676 | AE27: =AB27/$B$2 -> 879.50215 | AF27: =AG27*AF21 -> 125122.37 | AG27: =AC27 -> 0.5387931 | AH27: =AF27/$AF$10 -> 3.2370676 | AI27: =AF27/$B$2 -> 881.14348 | AJ27: =AK27*AJ21 -> 125355.44 | AK27: =AG27 -> 0.5387931 | AL27: =AJ27/$AJ$10 -> 3.2370676 | AM27: =AJ27/$B$2 -> 882.78481 | AN27: =AO27*AN21 -> 125934.88 | AO27: =AK27 -> 0.5387931 | AP27: =AN27/$AN$10 -> 3.2370676 | AQ27: =AN27/$B$2 -> 886.86534 | AR27: =AS27*AR21 -> 125824.82 | AS27: =AO27 -> 0.5387931 | AT27: =AR27/$AR$10 -> 3.2370676 | AU27: =AR27/$B$2 -> 886.09027 | AV27: =AW27*AV21 -> 126061.12 | AW27: =AS27 -> 0.5387931 | AX27: =AV27/$AV$10 -> 3.2370676 | AY27: =AV27/$B$2 -> 887.75439 | AZ27: =BA27*AZ21 -> 126061.12 | BA27: =AW27 -> 0.5387931 | BB27: =AZ27/$AZ$10 -> 3.2370676 | BC27: =AZ27/$B$2 -> 887.75439 | BD27: =BE27*BD21 -> 126407.49 | BE27: =BA27 -> 0.5387931 | BF27: =BD27/$BD$10 -> 3.2370676 | BG27: =BD27/$B$2 -> 890.19359 | BH27: =BI27*BH21 -> 126061.12 | BI27: =BE27 -> 0.5387931 | BJ27: =BH27/$BH$10 -> 3.2370676 | BK27: =BH27/$B$2 -> 887.75439 | BL27: =BM27*BL21 -> 126061.12 | BM27: =BI27 -> 0.5387931 | BN27: =BL27/$BL$10 -> 3.2370676 | BO27: =BL27/$B$2 -> 887.75439 | BP27: =BQ27*BP21 -> 126061.12 | BQ27: =BM27 -> 0.5387931 | BR27: =BP27/$BL$10 -> 3.2370676 | BS27: =BP27/$B$2 -> 887.75439
A28: Total Departemental Expenses | B28: =SUM(B24:B27) -> 2777299.8 | C28: =B28/B22 -> 0.48799538 | D28: =SUM(D24:D27) -> 2592623 | E28: =D28/D22 -> 0.52403143 | F28: =SUM(F24:F27) -> 2994276 | G28: =F28/F22 -> 0.47396534 | H28: =SUM(H24:H27) -> 3016609.4 | I28: =H28/H22 -> 0.45383977 | J28: =SUM(J24:J27) -> 2955572.9 | K28: =J28/J22 -> 0.45107825 | L28: =SUM(L24:L27) -> 2785200 | M28: =L28/L22 -> 0.41478772 | N28: =SUM(N24:N27) -> 2864400 | O28: =N28/N22 -> 0.42304568 | P28: =SUM(P24:P27) -> 772717.98 | Q28: =P28/P22 -> 0.48221414 | R28: =SUM(R24:R27) -> 906340.13 | S28: =R28/R22 -> 0.47107606 | T28: =SUM(T24:T27) -> 1946266.5 | U28: =T28/T22 -> 0.46149896 | V28: =SUM(V24:V27) -> 2601975 | W28: =V28/V22 -> 0.47150596 | X28: =SUM(X24:X27) -> 3092390 | Y28: =X28/X22 -> 0.49136603 | Z28: =X28/$X$10 -> 80.082204 | AA28: =X28/$B$2 -> 21777.394 | AB28: =SUM(AB24:AB27) -> 3101925.2 | AC28: =AB28/$AB$22 -> 0.49051825 | AD28: =AB28/$AB$10 -> 80.400331 | AE28: =AB28/$B$2 -> 21844.544 | AF28: =SUM(AF24:AF27) -> 3120505.1 | AG28: =AF28/$AF$22 -> 0.48964653 | AH28: =AF28/$AF$10 -> 80.731251 | AI28: =AF28/$B$2 -> 21975.388 | AJ28: =SUM(AJ24:AJ27) -> 3139235.4 | AK28: =AJ28/$AJ$22 -> 0.48877811 | AL28: =AJ28/$AJ$10 -> 81.064826 | AM28: =AJ28/$B$2 -> 22107.291 | AN28: =SUM(AN24:AN27) -> 3166827.4 | AO28: =AN28/$AN$22 -> 0.487913 | AP28: =AN28/$AN$10 -> 81.401075 | AQ28: =AN28/$B$2 -> 22301.602 | AR28: =SUM(AR24:AR27) -> 3177234.6 | AS28: =AR28/$AR$22 -> 0.48705122 | AT28: =AR28/$AR$10 -> 81.740021 | AU28: =AR28/$B$2 -> 22374.892 | AV28: =SUM(AV24:AV27) -> 3196507.1 | AW28: =AV28/$AV$22 -> 0.48619276 | AX28: =AV28/$AV$10 -> 82.081686 | AY28: =AV28/$B$2 -> 22510.613 | AZ28: =SUM(AZ24:AZ27) -> 3209919.3 | BA28: =AZ28/$AZ$22 -> 0.48533764 | BB28: =AZ28/$AZ$10 -> 82.426091 | BC28: =AZ28/$B$2 -> 22605.065 | BD28: =SUM(BD24:BD27) -> 3232295.7 | BE28: =BD28/$BD$22 -> 0.48448586 | BF28: =BD28/$BD$10 -> 82.773258 | BG28: =BD28/$B$2 -> 22762.646 | BH28: =SUM(BH24:BH27) -> 3237067.2 | BI28: =BH28/$BH$22 -> 0.48363744 | BJ28: =BH28/$BH$10 -> 83.12321 | BK28: =BH28/$B$2 -> 22796.248 | BL28: =SUM(BL24:BL27) -> 3250804.6 | BM28: =BL28/$BL$22 -> 0.48279238 | BN28: =BL28/$BL$10 -> 83.475968 | BO28: =BL28/$B$2 -> 22892.99 | BP28: =SUM(BP24:BP27) -> 3264652.3 | BQ28: =BP28/$BL$22 -> 0.48484895 | BR28: =BP28/$BL$10 -> 83.831556 | BS28: =BP28/$B$2 -> 22990.509
A29: Total Departemental Profit | B29: =B22-B28 -> 2913942.2 | C29: =B29/$B$22 -> 0.51200462 | D29: =D22-D28 -> 2354834 | E29: =D29/$D$22 -> 0.47596857 | F29: =F22-F28 -> 3323224 | G29: =F29/$F$22 -> 0.52603466 | H29: =H22-H28 -> 3630250.6 | I29: =H29/$H$22 -> 0.54616023 | J29: =J22-J28 -> 3596667.1 | K29: =J29/$J$22 -> 0.54892175 | L29: =L22-L28 -> 3929560 | M29: =L29/$L$22 -> 0.58521228 | N29: =N22-N28 -> 3906500 | O29: =N29/$N$22 -> 0.57695432 | P29: =P22-P28 -> 829719.44 | Q29: =P29/$P$22 -> 0.51778586 | R29: =R22-R28 -> 1017638.2 | S29: =R29/$R$22 -> 0.52892394 | T29: =T22-T28 -> 2271005.2 | U29: =T29/$T$22 -> 0.53850104 | V29: =V22-V28 -> 2916460 | W29: =V29/$V$22 -> 0.52849404 | X29: =X22-X28 -> 3201065 | Y29: =X29/$X$22 -> 0.50863397 | Z29: =X29/$X$10 -> 82.89651 | AA29: =X29/$B$2 -> 22542.711 | AB29: =AB22-AB28 -> 3221846 | AC29: =AB29/$AB$22 -> 0.50948175 | AD29: =AB29/$AB$10 -> 83.508619 | AE29: =AB29/$B$2 -> 22689.057 | AF29: =AF22-AF28 -> 3252469.9 | AG29: =AF29/$AF$22 -> 0.51035347 | AH29: =AF29/$AF$10 -> 84.145342 | AI29: =AF29/$B$2 -> 22904.718 | AJ29: =AJ22-AJ28 -> 3283383.2 | AK29: =AJ29/$AJ$22 -> 0.51122189 | AL29: =AJ29/$AJ$10 -> 84.787171 | AM29: =AJ29/$B$2 -> 23122.417 | AN29: =AN22-AN28 -> 3323730.1 | AO29: =AN29/$AN$22 -> 0.512087 | AP29: =AN29/$AN$10 -> 85.434149 | AQ29: =AN29/$B$2 -> 23406.55 | AR29: =AR22-AR28 -> 3346175.1 | AS29: =AR29/$AR$22 -> 0.51294878 | AT29: =AR29/$AR$10 -> 86.086315 | AU29: =AR29/$B$2 -> 23564.613 | AV29: =AV22-AV28 -> 3378060.4 | AW29: =AV29/$AV$22 -> 0.51380724 | AX29: =AV29/$AV$10 -> 86.743712 | AY29: =AV29/$B$2 -> 23789.157 | AZ29: =AZ22-AZ28 -> 3403866.7 | BA29: =AZ29/$AZ$22 -> 0.51466236 | BB29: =AZ29/$AZ$10 -> 87.406381 | BC29: =AZ29/$B$2 -> 23970.892 | BD29: =BD22-BD28 -> 3439303.9 | BE29: =BD29/$BD$22 -> 0.51551414 | BF29: =BD29/$BD$10 -> 88.074365 | BG29: =BD29/$B$2 -> 24220.45 | BH29: =BH22-BH28 -> 3456101.9 | BI29: =BH29/$BH$22 -> 0.51636256 | BJ29: =BH29/$BH$10 -> 88.747706 | BK29: =BH29/$B$2 -> 24338.746 | BL29: =BL22-BL28 -> 3482534.2 | BM29: =BL29/$BL$22 -> 0.51720762 | BN29: =BL29/$BL$10 -> 89.426448 | BO29: =BL29/$B$2 -> 24524.888 | BP29: =BP22-BP28 -> 3509178.4 | BQ29: =BP29/$BL$22 -> 0.52116469 | BR29: =BP29/$BL$10 -> 90.110633 | BS29: =BP29/$B$2 -> 24712.524
A30: Undistributed Operating Expenses
A31: Aministrative and General | B31: 598000 | C31: =B31/$B$22 -> 0.10507373 | D31: 598700 | E31: =D31/$D$22 -> 0.12101166 | F31: 658400 | G31: =F31/$F$22 -> 0.10421844 | H31: 684200 | I31: =H31/$H$22 -> 0.10293582 | J31: 603000 | K31: =J31/$J$22 -> 0.092029596 | L31: 854000 | M31: =L31/$L$22 -> 0.12718251 | N31: 407000 | O31: =N31/$N$22 -> 0.060110177 | P31: 407000 | Q31: =P31/$P$22 -> 0.25398808 | R31: 407000 | S31: =R31/$R$22 -> 0.21154085 | T31: 407000 | U31: =T31/$T$22 -> 0.096507893 | V31: 666000 | W31: =V31/$V$22 -> 0.12068639 | X31: 380000 | Y31: =X31/$X$22 -> 0.060380189 | Z31: =X31/$X$10 -> 9.8406855 | AA31: =X31/$B$2 -> 2676.0563 | AB31: =AE31*$B$2 -> 388049.09 | AC31: =Y31 -> 0.060380189 | AD31: =AB31/$AB$10 -> 10.058036 | AE31: =AA31*(1+Inflation) -> 2732.7401 | AF31: =AI31*$B$2 -> 396268.68 | AG31: =AF31/AF$22 -> 0.062179544 | AH31: =AF31/$AF$10 -> 10.251951 | AI31: =AE31*(1+Inflation) -> 2790.6245 | AJ31: =AM31*$B$2 -> 404662.37 | AK31: =AJ31/AJ$22 -> 0.063005823 | AL31: =AJ31/$AF$10 -> 10.469106 | AM31: =AI31*(1+Inflation) -> 2849.735 | AN31: =AQ31*$B$2 -> 413233.85 | AO31: =AN31/AN$22 -> 0.063666927 | AP31: =AN31/$AF$10 -> 10.690861 | AQ31: =AM31*(1+Inflation) -> 2910.0975 | AR31: =AU31*$B$2 -> 421986.9 | AS31: =AR31/AR$22 -> 0.064688087 | AT31: =AR31/$AF$10 -> 10.917313 | AU31: =AQ31*(1+Inflation) -> 2971.7387 | AV31: =AY31*$B$2 -> 430925.35 | AW31: =AV31/AV$22 -> 0.065544288 | AX31: =AV31/$AF$10 -> 11.148561 | AY31: =AU31*(1+Inflation) -> 3034.6855 | AZ31: =BC31*$B$2 -> 440053.13 | BA31: =AZ31/AZ$22 -> 0.066535738 | BB31: =AZ31/$AF$10 -> 11.384708 | BC31: =AY31*(1+Inflation) -> 3098.9657 | BD31: =BG31*$B$2 -> 449374.25 | BE31: =BD31/BD$22 -> 0.067356298 | BF31: =BD31/$AF$10 -> 11.625857 | BG31: =BC31*(1+Inflation) -> 3164.6074 | BH31: =BK31*$B$2 -> 458892.82 | BI31: =BH31/BH$22 -> 0.068561366 | BJ31: =BH31/$AF$10 -> 11.872114 | BK31: =BG31*(1+Inflation) -> 3231.6396 | BL31: =BO31*$B$2 -> 468613 | BM31: =BL31/BL$22 -> 0.069595934 | BN31: =BL31/$AF$10 -> 12.123587 | BO31: =BK31*(1+Inflation) -> 3300.0916 | BP31: =BS31*$B$2 -> 478539.08 | BQ31: =BP31/BP$22 -> 0.070645267 | BR31: =BP31/$AF$10 -> 12.380386 | BS31: =BO31*(1+Inflation) -> 3369.9935
A32: Sales And Marketing | B32: 424700 | C32: =B32/$B$22 -> 0.07462343 | D32: 403250 | E32: =D32/$D$22 -> 0.081506519 | F32: 472140 | G32: =F32/$F$22 -> 0.074735259 | H32: 462370 | I32: =H32/$H$22 -> 0.069562169 | J32: 433000 | K32: =J32/$J$22 -> 0.06608427 | L32: 456000 | M32: =L32/$L$22 -> 0.067910097 | N32: 450000 | O32: =N32/$N$22 -> 0.066460884 | P32: 450000 | Q32: =P32/$P$22 -> 0.2808222 | R32: 450000 | S32: =R32/$R$22 -> 0.23389037 | T32: 450000 | U32: =T32/$T$22 -> 0.10670406 | V32: 366000 | W32: =V32/$V$22 -> 0.066323151 | X32: 230000 | Y32: =X32/$X$22 -> 0.036545904 | Z32: =X32/$X$10 -> 5.9562044 | AA32: =X32/$B$2 -> 1619.7183 | AB32: =AE32*$B$2 -> 234871.82 | AC32: =Y32 -> 0.036545904 | AD32: =AB32/$AB$10 -> 6.0877587 | AE32: =AA32*(1+Inflation) -> 1654.0269 | AF32: =AI32*$B$2 -> 239846.83 | AG32: =AF32/AF$22 -> 0.037634987 | AH32: =AF32/$AF$10 -> 6.2051285 | AI32: =AE32*(1+Inflation) -> 1689.0622 | AJ32: =AM32*$B$2 -> 244927.22 | AK32: =AJ32/AJ$22 -> 0.038135103 | AL32: =AJ32/$AF$10 -> 6.3365644 | AM32: =AI32*(1+Inflation) -> 1724.8396 | AN32: =AQ32*$B$2 -> 250115.23 | AO32: =AN32/AN$22 -> 0.038535245 | AP32: =AN32/$AF$10 -> 6.4707843 | AQ32: =AM32*(1+Inflation) -> 1761.3748 | AR32: =AU32*$B$2 -> 255413.12 | AS32: =AR32/AR$22 -> 0.039153316 | AT32: =AR32/$AF$10 -> 6.6078473 | AU32: =AQ32*(1+Inflation) -> 1798.684 | AV32: =AY32*$B$2 -> 260823.24 | AW32: =AV32/AV$22 -> 0.039671543 | AX32: =AV32/$AF$10 -> 6.7478135 | AY32: =AU32*(1+Inflation) -> 1836.7834 | AZ32: =BC32*$B$2 -> 266347.95 | BA32: =AZ32/AZ$22 -> 0.040271631 | BB32: =AZ32/$AF$10 -> 6.8907445 | BC32: =AY32*(1+Inflation) -> 1875.6898 | BD32: =BG32*$B$2 -> 271989.68 | BE32: =BD32/BD$22 -> 0.040768285 | BF32: =BD32/$AF$10 -> 7.036703 | BG32: =BC32*(1+Inflation) -> 1915.4203 | BH32: =BK32*$B$2 -> 277750.92 | BI32: =BH32/BH$22 -> 0.041497669 | BJ32: =BH32/$AF$10 -> 7.1857531 | BK32: =BG32*(1+Inflation) -> 1955.9924 | BL32: =BO32*$B$2 -> 283634.19 | BM32: =BL32/BL$22 -> 0.042123855 | BN32: =BL32/$AF$10 -> 7.3379604 | BO32: =BK32*(1+Inflation) -> 1997.4238 | BP32: =BS32*$B$2 -> 289642.07 | BQ32: =BP32/BP$22 -> 0.042758977 | BR32: =BP32/$AF$10 -> 7.4933918 | BS32: =BO32*(1+Inflation) -> 2039.7329
A33: Heat light and Power | B33: 324500 | C33: =B33/$B$22 -> 0.057017431 | D33: 314780 | E33: =D33/$D$22 -> 0.063624606 | F33: 384520 | G33: =F33/$F$22 -> 0.060865849 | H33: 395470 | I33: =H33/$H$22 -> 0.059497266 | J33: 395000 | K33: =J33/$J$22 -> 0.060284727 | L33: 266000 | M33: =L33/$L$22 -> 0.039614223 | N33: 297000 | O33: =N33/$N$22 -> 0.043864183 | P33: 297000 | Q33: =P33/$P$22 -> 0.18534265 | R33: 297000 | S33: =R33/$R$22 -> 0.15436764 | T33: 297000 | U33: =T33/$T$22 -> 0.070424679 | V33: 363000 | W33: =V33/$V$22 -> 0.065779519 | X33: 340000 | Y33: =X33/$X$22 -> 0.054024379 | Z33: =X33/$X$10 -> 8.8048239 | AA33: =X33/$B$2 -> 2394.3662 | AB33: =AE33*$B$2 -> 347201.82 | AC33: =Y33 -> 0.054024379 | AD33: =AB33/$AB$10 -> 8.9992955 | AE33: =AA33*(1+Inflation) -> 2445.0832 | AF33: =AI33*$B$2 -> 354556.18 | AG33: =AF33/AF$22 -> 0.055634329 | AH33: =AF33/$AF$10 -> 9.1727986 | AI33: =AE33*(1+Inflation) -> 2496.8745 | AJ33: =AM33*$B$2 -> 362066.33 | AK33: =AJ33/AJ$22 -> 0.056373631 | AL33: =AJ33/$AF$10 -> 9.3670951 | AM33: =AI33*(1+Inflation) -> 2549.7629 | AN33: =AQ33*$B$2 -> 369735.55 | AO33: =AN33/AN$22 -> 0.056965145 | AP33: =AN33/$AF$10 -> 9.5655072 | AQ33: =AM33*(1+Inflation) -> 2603.7715 | AR33: =AU33*$B$2 -> 377567.22 | AS33: =AR33/AR$22 -> 0.057878815 | AT33: =AR33/$AF$10 -> 9.7681221 | AU33: =AQ33*(1+Inflation) -> 2658.9241 | AV33: =AY33*$B$2 -> 385564.78 | AW33: =AV33/AV$22 -> 0.05864489 | AX33: =AV33/$AF$10 -> 9.9750287 | AY33: =AU33*(1+Inflation) -> 2715.245 | AZ33: =BC33*$B$2 -> 393731.75 | BA33: =AZ33/AZ$22 -> 0.059531976 | BB33: =AZ33/$AF$10 -> 10.186318 | BC33: =AY33*(1+Inflation) -> 2772.7588 | BD33: =BG33*$B$2 -> 402071.7 | BE33: =BD33/BD$22 -> 0.060266161 | BF33: =BD33/$AF$10 -> 10.402083 | BG33: =BC33*(1+Inflation) -> 2831.4908 | BH33: =BK33*$B$2 -> 410588.31 | BI33: =BH33/BH$22 -> 0.06134438 | BJ33: =BH33/$AF$10 -> 10.622418 | BK33: =BG33*(1+Inflation) -> 2891.467 | BL33: =BO33*$B$2 -> 419285.32 | BM33: =BL33/BL$22 -> 0.062270046 | BN33: =BL33/$AF$10 -> 10.84742 | BO33: =BK33*(1+Inflation) -> 2952.7135 | BP33: =BS33*$B$2 -> 428166.54 | BQ33: =BP33/BP$22 -> 0.063208923 | BR33: =BP33/$AF$10 -> 11.077188 | BS33: =BO33*(1+Inflation) -> 3015.2573
A34: Repairs and Maintenance | B34: 271600 | C34: =B34/$B$22 -> 0.047722448 | D34: 288047 | E34: =D34/$D$22 -> 0.058221224 | F34: 324940 | G34: =F34/$F$22 -> 0.051434903 | H34: 340360 | I34: =H34/$H$22 -> 0.051206133 | J34: 300000 | K34: =J34/$J$22 -> 0.045785869 | L34: 348000 | M34: =L34/$L$22 -> 0.051826126 | N34: 322000 | O34: =N34/$N$22 -> 0.047556455 | P34: 322000 | Q34: =P34/$P$22 -> 0.20094388 | R34: 322000 | S34: =R34/$R$22 -> 0.16736155 | T34: 322000 | U34: =T34/$T$22 -> 0.076352682 | V34: 595000 | W34: =V34/$V$22 -> 0.10782042 | X34: 400000 | Y34: =X34/$X$22 -> 0.063558093 | Z34: =X34/$X$10 -> 10.358616 | AA34: =X34/$B$2 -> 2816.9014 | AB34: =AE34*$B$2 -> 408472.73 | AC34: =Y34 -> 0.063558093 | AD34: =AB34/$AB$10 -> 10.587406 | AE34: =AA34*(1+Inflation) -> 2876.5685 | AF34: =AI34*$B$2 -> 417124.92 | AG34: =AF34/AF$22 -> 0.065452151 | AH34: =AF34/$AF$10 -> 10.791528 | AI34: =AE34*(1+Inflation) -> 2937.4995 | AJ34: =AM34*$B$2 -> 425960.39 | AK34: =AJ34/AJ$22 -> 0.066321919 | AL34: =AJ34/$AF$10 -> 11.020112 | AM34: =AI34*(1+Inflation) -> 2999.721 | AN34: =AQ34*$B$2 -> 434983 | AO34: =AN34/AN$22 -> 0.067017818 | AP34: =AN34/$AF$10 -> 11.253538 | AQ34: =AM34*(1+Inflation) -> 3063.2606 | AR34: =AU34*$B$2 -> 444196.73 | AS34: =AR34/AR$22 -> 0.068092724 | AT34: =AR34/$AF$10 -> 11.491908 | AU34: =AQ34*(1+Inflation) -> 3128.146 | AV34: =AY34*$B$2 -> 453605.63 | AW34: =AV34/AV$22 -> 0.068993988 | AX34: =AV34/$AF$10 -> 11.735328 | AY34: =AU34*(1+Inflation) -> 3194.4058 | AZ34: =BC34*$B$2 -> 463213.82 | BA34: =AZ34/AZ$22 -> 0.070037619 | BB34: =AZ34/$AF$10 -> 11.983903 | BC34: =AY34*(1+Inflation) -> 3262.0691 | BD34: =BG34*$B$2 -> 473025.53 | BE34: =BD34/BD$22 -> 0.070901366 | BF34: =BD34/$AF$10 -> 12.237744 | BG34: =BC34*(1+Inflation) -> 3331.1657 | BH34: =BK34*$B$2 -> 483045.07 | BI34: =BH34/BH$22 -> 0.072169859 | BJ34: =BH34/$AF$10 -> 12.496962 | BK34: =BG34*(1+Inflation) -> 3401.7259 | BL34: =BO34*$B$2 -> 493276.84 | BM34: =BL34/BL$22 -> 0.073258878 | BN34: =BL34/$AF$10 -> 12.76167 | BO34: =BK34*(1+Inflation) -> 3473.7806 | BP34: =BS34*$B$2 -> 503725.34 | BQ34: =BP34/BP$22 -> 0.074363439 | BR34: =BP34/$AF$10 -> 13.031986 | BS34: =BO34*(1+Inflation) -> 3547.3616
A35: Total Undistributed Undistributed Expenses | B35: =SUM(B31:B34) -> 1618800 | C35: =B35/$B$22 -> 0.28443704 | D35: =SUM(D31:D34) -> 1604777 | E35: =D35/$D$22 -> 0.32436401 | F35: =SUM(F31:F34) -> 1840000 | G35: =F35/$F$22 -> 0.29125445 | H35: =SUM(H31:H34) -> 1882400 | I35: =H35/$H$22 -> 0.28320139 | J35: =SUM(J31:J34) -> 1731000 | K35: =J35/$J$22 -> 0.26418446 | L35: =SUM(L31:L34) -> 1924000 | M35: =L35/$L$22 -> 0.28653295 | N35: =SUM(N31:N34) -> 1476000 | O35: =N35/$N$22 -> 0.2179917 | P35: =SUM(P31:P34) -> 1476000 | Q35: =P35/$P$22 -> 0.92109681 | R35: =SUM(R31:R34) -> 1476000 | S35: =R35/$R$22 -> 0.76716041 | T35: =SUM(T31:T34) -> 1476000 | U35: =T35/$T$22 -> 0.34998931 | V35: =SUM(V31:V34) -> 1990000 | W35: =V35/$V$22 -> 0.36060948 | X35: =SUM(X31:X34) -> 1350000 | Y35: =X35/$X$22 -> 0.21450856 | Z35: =X35/$X$10 -> 34.96033 | AA35: =X35/$B$2 -> 9507.0423 | AB35: =SUM(AB31:AB34) -> 1378595.5 | AC35: =AB35/$AB$22 -> 0.21800211 | AD35: =AB35/$AB$10 -> 35.732497 | AE35: =AB35/$B$2 -> 9708.4187 | AF35: =SUM(AF31:AF34) -> 1407796.6 | AG35: =AF35/$AF$22 -> 0.22090101 | AH35: =AF35/$AF$10 -> 36.421406 | AI35: =AF35/$B$2 -> 9914.0607 | AJ35: =SUM(AJ31:AJ34) -> 1437616.3 | AK35: =AJ35/$AJ$22 -> 0.22383648 | AL35: =AJ35/$AJ$10 -> 37.123726 | AM35: =AJ35/$B$2 -> 10124.058 | AN35: =SUM(AN31:AN34) -> 1468067.6 | AO35: =AN35/$AN$22 -> 0.22618513 | AP35: =AN35/$AN$10 -> 37.735648 | AQ35: =AN35/$B$2 -> 10338.504 | AR35: =SUM(AR31:AR34) -> 1499164 | AS35: =AR35/$AR$22 -> 0.22981294 | AT35: =AR35/$AR$10 -> 38.568664 | AU35: =AR35/$B$2 -> 10557.493 | AV35: =SUM(AV31:AV34) -> 1530919 | AW35: =AV35/$AV$22 -> 0.23285471 | AX35: =AV35/$AV$10 -> 39.311789 | AY35: =AV35/$B$2 -> 10781.12 | AZ35: =SUM(AZ31:AZ34) -> 1563346.6 | BA35: =AZ35/$AZ$22 -> 0.23637696 | BB35: =AZ35/$AZ$10 -> 40.144484 | BC35: =AZ35/$B$2 -> 11009.483 | BD35: =SUM(BD31:BD34) -> 1596461.2 | BE35: =BD35/$BD$22 -> 0.23929211 | BF35: =BD35/$BD$10 -> 40.882488 | BG35: =BD35/$B$2 -> 11242.684 | BH35: =SUM(BH31:BH34) -> 1630277.1 | BI35: =BH35/$BH$22 -> 0.24357328 | BJ35: =BH35/$BH$10 -> 41.863162 | BK35: =BH35/$B$2 -> 11480.825 | BL35: =SUM(BL31:BL34) -> 1664809.3 | BM35: =BL35/$BL$22 -> 0.24724871 | BN35: =BL35/$BL$10 -> 42.7499 | BO35: =BL35/$B$2 -> 11724.009 | BP35: =SUM(BP31:BP34) -> 1700073 | BQ35: =BP35/$BL$22 -> 0.25248589 | BR35: =BP35/$BL$10 -> 43.65542 | BS35: =BP35/$B$2 -> 11972.345
A36: Gross Operating Profit (GOP) | B36: =B29-B35 -> 1295142.2 | C36: =B36/$B$22 -> 0.22756758 | D36: =D29-D35 -> 750057.04 | E36: =D36/$D$22 -> 0.15160456 | F36: =F29-F35 -> 1483224 | G36: =F36/$F$22 -> 0.23478021 | H36: =H29-H35 -> 1747850.6 | I36: =H36/$H$22 -> 0.26295883 | J36: =J29-J35 -> 1865667.1 | K36: =J36/$J$22 -> 0.28473729 | L36: =L29-L35 -> 2005560 | M36: =L36/$L$22 -> 0.29867933 | N36: =N29-N35 -> 2430500 | O36: =N36/$N$22 -> 0.35896262 | P36: =P29-P35 -> -646280.56 | Q36: =P36/$P$22 -> -0.40331095 | R36: =R29-R35 -> -458361.81 | S36: =R36/$R$22 -> -0.23823648 | T36: =T29-T35 -> 795005.18 | U36: =T36/$T$22 -> 0.18851173 | V36: =V29-V35 -> 926460 | W36: =V36/$V$22 -> 0.16788455 | X36: =X29-X35 -> 1851065 | Y36: =X36/$X$22 -> 0.2941254 | Z36: =X36/$X$10 -> 47.93618 | AA36: =X36/$B$2 -> 13035.669 | AB36: =AB29-AB35 -> 1843250.6 | AC36: =AB36/$AB$22 -> 0.29147964 | AD36: =AB36/$AB$10 -> 47.776122 | AE36: =AB36/$B$2 -> 12980.638 | AF36: =AF29-AF35 -> 1844673.3 | AG36: =AF36/$AF$22 -> 0.28945246 | AH36: =AF36/$AF$10 -> 47.723936 | AI36: =AF36/$B$2 -> 12990.657 | AJ36: =AJ29-AJ35 -> 1845766.9 | AK36: =AJ36/$AJ$22 -> 0.28738542 | AL36: =AJ36/$AJ$10 -> 47.663445 | AM36: =AJ36/$B$2 -> 12998.359 | AN36: =AN29-AN35 -> 1855662.5 | AO36: =AN36/$AN$22 -> 0.28590186 | AP36: =AN36/$AN$10 -> 47.698501 | AQ36: =AN36/$B$2 -> 13068.046 | AR36: =AR29-AR35 -> 1847011.1 | AS36: =AR36/$AR$22 -> 0.28313584 | AT36: =AR36/$AR$10 -> 47.517651 | AU36: =AR36/$B$2 -> 13007.12 | AV36: =AV29-AV35 -> 1847141.4 | AW36: =AV36/$AV$22 -> 0.28095253 | AX36: =AV36/$AV$10 -> 47.431923 | AY36: =AV36/$B$2 -> 13008.038 | AZ36: =AZ29-AZ35 -> 1840520 | BA36: =AZ36/$AZ$22 -> 0.2782854 | BB36: =AZ36/$AZ$10 -> 47.261897 | BC36: =AZ36/$B$2 -> 12961.409 | BD36: =BD29-BD35 -> 1842842.8 | BE36: =BD36/$BD$22 -> 0.27622203 | BF36: =BD36/$BD$10 -> 47.191877 | BG36: =BD36/$B$2 -> 12977.766 | BH36: =BH29-BH35 -> 1825824.8 | BI36: =BH36/$BH$22 -> 0.27278928 | BJ36: =BH36/$BH$10 -> 46.884544 | BK36: =BH36/$B$2 -> 12857.921 | BL36: =BL29-BL35 -> 1817724.8 | BM36: =BL36/$BL$22 -> 0.26995891 | BN36: =BL36/$BL$10 -> 46.676548 | BO36: =BL36/$B$2 -> 12800.879 | BP36: =BP29-BP35 -> 1809105.4 | BQ36: =BP36/$BL$22 -> 0.2686788 | BR36: =BP36/$BL$10 -> 46.455213 | BS36: =BP36/$B$2 -> 12740.179
A37: Management Fee | B37: 0 | C37: =B37/$B$22 -> 0 | D37: 0 | E37: =D37/$D$22 -> 0 | F37: 0 | G37: =F37/$F$22 -> 0 | H37: 0 | I37: =H37/$H$22 -> 0 | J37: 0 | K37: =J37/$J$22 -> 0 | L37: 0 | M37: =L37/$L$22 -> 0 | N37: 0 | O37: =N37/$N$22 -> 0 | P37: 0 | Q37: =P37/$P$22 -> 0 | R37: 0 | S37: =R37/$R$22 -> 0 | T37: 0 | U37: =T37/$T$22 -> 0 | V37: 0 | W37: =V37/$V$22 -> 0 | X37: 0 | Y37: =X37/$X$22 -> 0 | Z37: =X37/$X$10 -> 0 | AA37: =X37/$B$2 -> 0 | AB37: 0 | AC37: =AB37/$AB$22 -> 0 | AD37: =AB37/$AB$10 -> 0 | AE37: =AB37/$B$2 -> 0 | AF37: 0 | AG37: =AF37/$AF$22 -> 0 | AH37: =AF37/$AF$10 -> 0 | AI37: =AF37/$B$2 -> 0 | AJ37: 0 | AK37: =AJ37/$AJ$22 -> 0 | AL37: =AJ37/$AJ$10 -> 0 | AM37: =AJ37/$B$2 -> 0 | AN37: 0 | AO37: =AN37/$AN$22 -> 0 | AP37: =AN37/$AN$10 -> 0 | AQ37: =AN37/$B$2 -> 0 | AR37: 0 | AS37: =AR37/$AR$22 -> 0 | AT37: =AR37/$AR$10 -> 0 | AU37: =AR37/$B$2 -> 0 | AV37: 0 | AW37: =AV37/$AV$22 -> 0 | AX37: =AV37/$AV$10 -> 0 | AY37: =AV37/$B$2 -> 0 | AZ37: 0 | BA37: =AZ37/$AZ$22 -> 0 | BB37: =AZ37/$AZ$10 -> 0 | BC37: =AZ37/$B$2 -> 0 | BD37: 0 | BE37: =BD37/$BD$22 -> 0 | BF37: =BD37/$BD$10 -> 0 | BG37: =BD37/$B$2 -> 0 | BH37: 0 | BI37: =BH37/$BH$22 -> 0 | BJ37: =BH37/$BH$10 -> 0 | BK37: =BH37/$B$2 -> 0 | BL37: 0 | BM37: =BL37/$BL$22 -> 0 | BN37: =BL37/$BL$10 -> 0 | BO37: =BL37/$B$2 -> 0 | BP37: 0 | BQ37: =BP37/$BL$22 -> 0 | BR37: =BP37/$BL$10 -> 0 | BS37: =BP37/$B$2 -> 0
